
Traceback (most recent call last):
  File "/opt/local/Library/Frameworks/Python.framework/Versions/3.6/lib/python3.6/site-packages/pyp2p/sock.py", line 195, in connect
    self.s.connect((addr, int(port)))
ConnectionRefusedError: [Errno 61] Connection refused
 <class 'ConnectionRefusedError'> sock.py 195 [Errno 61] Connection refused